Namespace(batch_size=32, data_dir='/root/dataset/Osteoporosis/Sagittal_Contrast_Final_1/', epochs=60, log='logs/Ordinal', lr=0.0001, n_gpu=4, num_classes=3, phase='train', seed=0, weight_decay=0.001, workers=16)
ordinal.py:41: UserWarning: You have chosen to seed training. This will turn on the CUDNN deterministic setting, which can slow down your training considerably! You may see unexpected behavior when restarting from checkpoints.
  warnings.warn('You have chosen to seed training. '
Traceback (most recent call last):
  File "ordinal.py", line 248, in <module>
    main(args)
  File "ordinal.py", line 96, in main
    train(model, train_loader, criterion, optimizer,
  File "ordinal.py", line 135, in train
    for batch_idx, (data, target) in enumerate(train_loader):
  File "/root/anaconda3/lib/python3.8/site-packages/torch/utils/data/dataloader.py", line 435, in __next__
    data = self._next_data()
  File "/root/anaconda3/lib/python3.8/site-packages/torch/utils/data/dataloader.py", line 1085, in _next_data
    return self._process_data(data)
  File "/root/anaconda3/lib/python3.8/site-packages/torch/utils/data/dataloader.py", line 1111, in _process_data
    data.reraise()
  File "/root/anaconda3/lib/python3.8/site-packages/torch/_utils.py", line 428, in reraise
    raise self.exc_type(msg)
ValueError: Caught ValueError in DataLoader worker process 0.
Original Traceback (most recent call last):
  File "/root/anaconda3/lib/python3.8/site-packages/torch/utils/data/_utils/worker.py", line 198, in _worker_loop
    data = fetcher.fetch(index)
  File "/root/anaconda3/lib/python3.8/site-packages/torch/utils/data/_utils/fetch.py", line 44, in fetch
    data = [self.dataset[idx] for idx in possibly_batched_index]
  File "/root/anaconda3/lib/python3.8/site-packages/torch/utils/data/_utils/fetch.py", line 44, in <listcomp>
    data = [self.dataset[idx] for idx in possibly_batched_index]
  File "/root/work/KNU_Medical_CT/datasets/knu_ct.py", line 98, in __getitem__
    image = self.transforms(image)
  File "/root/anaconda3/lib/python3.8/site-packages/torchvision/transforms/transforms.py", line 67, in __call__
    img = t(img)
  File "/root/anaconda3/lib/python3.8/site-packages/torch/nn/modules/module.py", line 727, in _call_impl
    result = self.forward(*input, **kwargs)
  File "/root/anaconda3/lib/python3.8/site-packages/torchvision/transforms/transforms.py", line 267, in forward
    return F.resize(img, self.size, self.interpolation)
  File "/root/anaconda3/lib/python3.8/site-packages/torchvision/transforms/functional.py", line 310, in resize
    return F_pil.resize(img, size=size, interpolation=interpolation)
  File "/root/anaconda3/lib/python3.8/site-packages/torchvision/transforms/functional_pil.py", line 423, in resize
    return img.resize((ow, oh), interpolation)
  File "/root/anaconda3/lib/python3.8/site-packages/PIL/Image.py", line 1878, in resize
    raise ValueError(
ValueError: Unknown resampling filter (224). Use Image.NEAREST (0), Image.LANCZOS (1), Image.BILINEAR (2), Image.BICUBIC (3), Image.BOX (4) or Image.HAMMING (5)

